<?xml version="1.0" ?>
<sdf version="1.8">
    <world name="assn_2">
        <scene>
            <sky>
                 <clouds>
                     <speed>0</speed>
                </clouds>
            </sky>
            <shadows>1</shadows>
            
            <ambient>0 1 1 1</ambient>
             <background>0 0.7 0.8 1</background>
            <shadows>1</shadows>
        </scene>

        <physics name="1ms" type="ignored">
            <max_step_size>0.001</max_step_size>
            <real_time_factor>1.0</real_time_factor>
        </physics>
        <plugin
            filename="libignition-gazebo-physics-system.so"
            name="ignition::gazebo::systems::Physics">
        </plugin>
        <plugin
            filename="libignition-gazebo-user-commands-system.so"
            name="ignition::gazebo::systems::UserCommands">
        </plugin>
        <plugin
            filename="libignition-gazebo-scene-broadcaster-system.so"
            name="ignition::gazebo::systems::SceneBroadcaster">
        </plugin>
        <plugin name="stereo_camera_controller"
                filename="stereo_camera/libDdsStereoCameraPlugin.so">
            <update_rate>0.0</update_rate>
            <dds_domain_id>0</dds_domain_id>
            <frame_name>camera_link</frame_name>
            <topic_name_image>image_raw</topic_name_image>
            <topic_name_camera_info>camera_info</topic_name_camera_info>
            <frameName>left_camera_optical_frame</frameName>
            <hack_baseline>0.07</hack_baseline>
            <distortion_k1>0.0</distortion_k1>
            <distortion_k2>0.0</distortion_k2>
            <distortion_k3>0.0</distortion_k3>
            <distortion_t1>0.0</distortion_t1>
            <distortion_t2>0.0</distortion_t2>
            <cx_prime>0.0</cx_prime>
            <cy>0.0</cy>
            <focal_length>0</focal_length>
            <border_crop>true</border_crop>
        </plugin>
        <plugin name="ignition::gazebo::systems::Sensors" filename="ignition-gazebo-sensors-system">
            <render_engine>ogre2</render_engine>
        </plugin>
        <gui fullscreen="0">
            <plugin filename="GzScene3D" name="3D View">
                <ignition-gui>
                <title>3D View</title>
                <property type="bool" key="showTitleBar">false</property>
                <property type="string" key="state">docked</property>
                </ignition-gui>
                <engine>ogre2</engine>
                <scene>scene</scene>
                <ambient_light>0.4 0.4 0.4</ambient_light>
                <background_color>0.8 0.8 0.8</background_color>
            </plugin>
            <plugin filename="WorldControl" name="World control">
                <ignition-gui>
                <title>World control</title>
                <property type="bool" key="showTitleBar">false</property>
                <property type="bool" key="resizable">false</property>
                <property type="double" key="height">72</property>
                <property type="double" key="width">121</property>
                <property type="double" key="z">1</property>

                <property type="string" key="state">floating</property>
                <anchors target="3D View">
                     <line own="left" target="left"/>
                    <line own="bottom" target="bottom"/>
                </anchors>
                </ignition-gui>

                <play_pause>true</play_pause>
                <step>true</step>
                <start_paused>true</start_paused>
                <service>/world/world_demo/control</service>
                <stats_topic>/world/world_demo/stats</stats_topic>
            </plugin>
            <plugin filename="WorldStats" name="World stats">
                <ignition-gui>
                <title>World stats</title>
                <property type="bool" key="showTitleBar">false</property>
                <property type="bool" key="resizable">false</property>
                <property type="double" key="height">110</property>
                <property type="double" key="width">290</property>
                <property type="double" key="z">1</property>

                <property type="string" key="state">floating</property>
                <anchors target="3D View">
                     <line own="right" target="right"/>
                    <line own="bottom" target="bottom"/>
                </anchors>
                </ignition-gui>

                <sim_time>true</sim_time>
                <real_time>true</real_time>
                <real_time_factor>true</real_time_factor>
                <iterations>true</iterations>
                <topic>/world/world_demo/stats</topic>

            </plugin>
            <plugin filename="EntityTree" name="Entity tree">
            </plugin>
            <plugin filename="ImageDisplay" name="front_depth_camera">
                 <topic>/world/auv/model/auv/link/front_depth_camera/sensor/front_depth_camera/depth_image</topic>
                 <topic_picker>0</topic_picker>
                 <ignition-gui>
                     <title>front depth camera</title>
                     <property key="state" type="string">floating</property>
                    <property type="double" key="height">300</property>
                    <property type="double" key="width">300</property>
                     <property type="double" key="x">1</property>
                    <property type="double" key="y">1</property>
                    <property type="double" key="z">1</property>
                 </ignition-gui>
            </plugin>
            <plugin filename="ImageDisplay" name="front_camera">
                 <topic>/world/auv/model/auv/link/front_camera/sensor/front_camera/image</topic>
                 <topic_picker>0</topic_picker>
                <ignition-gui>
                     <title>front camera</title>
                    <property key="state" type="string">floating</property>
                     <property type="double" key="height">300</property>
                    <property type="double" key="width">300</property>
                    <property type="double" key="x">300</property>
                    <property type="double" key="y">1</property>
                     <property type="double" key="z">1</property>
                </ignition-gui>
            </plugin> 





            <plugin filename='KeyPublisher' name='Key Publisher'/>
        
        </gui>    

        <light type="directional" name="sun">
            <cast_shadows>true</cast_shadows>
            <pose>0 0 10 0 0 0</pose>
            <diffuse>0.8 0.8 0.8 1</diffuse>
            <specular>0.2 0.2 0.2 1</specular>
            <attenuation>
                <range>1000</range>
                <constant>0.9</constant>
                <linear>0.01</linear>
                <quadratic>0.001</quadratic>
            </attenuation>
            <direction>-0.5 0.1 -0.9</direction>
        </light>

        <model name="ground_plane">
            <static>true</static>
            <link name="link">
                <collision name="collision">
                <geometry>
                    <plane>
                    <normal>0 0 1</normal>
                    </plane>
                </geometry>
                </collision>
                <visual name="visual">
                <geometry>
                    <plane>
                    <normal>0 0 1</normal>
                    <size>100 100</size>
                    </plane>
                </geometry>
                <material>
                    <ambient>0.8 0.8 0.8 1</ambient>
                    <diffuse>0.8 0.8 0.8 1</diffuse>
                    <specular>0.8 0.8 0.8 1</specular>
                </material>
                <surface>
                    <friction>
                        <ode>
                             <mu>0.5</mu>
                             <mu2>0.5</mu2>
                        </ode>
                    </friction>
                </surface>

                </visual>
            </link>
        </model>
            <model name='mars_rover' canonical_link='chassis'>
                <pose relative_to='world'>0 0 0.35 0 0 0</pose>
                <frame name='stereocam_frame' attached_to='chassis'>
                    <pose>0.4 0 0.26 0 0 0</pose>

                </frame>     
            <link name='chassis'>    
                    <pose relative_to='__model__'>0.5 0 0.4 0 0 0</pose>
            <inertial> <!--inertial properties of the link mass, inertia matix-->
                <mass>1.14395</mass>
                <inertia>
                    <ixx>0.095329</ixx>
                    <ixy>0</ixy>
                    <ixz>0</ixz>
                    <iyy>0.381317</iyy>
                    <iyz>0</iyz>
                    <izz>0.476646</izz>
                </inertia>
            </inertial>  
            <visual name='visual'>
                <geometry>
                    <box>
                         <size>1.0 0.52 0.52</size>
                    </box>
                </geometry>
                <!--let's add color to our link-->
                <material>
                    <ambient>0.0 0.0 1.0 1</ambient>
                    <diffuse>0.0 0.0 1.0 1</diffuse>
                    <specular>0.0 0.0 1.0 1</specular>
                </material>
            </visual> 
                <collision name='collision'>
                    <geometry>
                        <box>
                            <size>0.80 0.52 0.53</size>
                        </box>
                    </geometry>
                </collision>
            </link>

            <link name='left_front_wheel'> 
                <pose relative_to="chassis">0.45 0.31 -0.435 -1.5707 0 0</pose> <!--angles are in radian-->
                <inertial>
                    <mass>5</mass>
                    <inertia>
                        <ixx>0.043333</ixx>
                        <ixy>0</ixy>
                        <ixz>0</ixz>
                        <iyy>0.043333</iyy>
                        <iyz>0</iyz>
                        <izz>0.08</izz>
                    </inertia>
                </inertial>
                <visual name='visual'>
                    <geometry>
                        <cylinder>
                            <radius>0.175</radius> 
                            <length>0.1</length>
                        </cylinder>
                    </geometry>
                    <material>
                        <ambient>1.0 0.0 0.0 1</ambient>
                        <diffuse>1.0 0.0 0.0 1</diffuse>
                        <specular>1.0 0.0 0.0 1</specular>
                    </material>
                    <surface>
                        <friction>
                            <ode>
                                <mu>0.5</mu>
                                <mu2>0.5</mu2>
                            </ode>
                        </friction>
                    </surface>
                </visual>
                <collision name='collision'>
                    <geometry>
                        <cylinder>
                            <radius>0.175</radius>
                            <length>0.1</length>
                        </cylinder>
                    </geometry>
                </collision>
            </link>           
            <link name='right_front_wheel'> 
                <pose relative_to="chassis">0.45 -0.31 -0.435 -1.5707 0 0</pose> <!--angles are in radian-->
                <inertial>
                    <mass>5</mass>
                    <inertia>
                        <ixx>0.043333</ixx>
                        <ixy>0</ixy>
                        <ixz>0</ixz>
                        <iyy>0.043333</iyy>
                        <iyz>0</iyz>
                        <izz>0.08</izz>
                    </inertia>
                </inertial>
                <visual name='visual'>
                    <geometry>
                        <cylinder>
                            <radius>0.175</radius> 
                            <length>0.1</length>
                        </cylinder>
                    </geometry>
                    <material>
                        <ambient>1.0 0.0 0.0 1</ambient>
                        <diffuse>1.0 0.0 0.0 1</diffuse>
                        <specular>1.0 0.0 0.0 1</specular>
                    </material>
                    <surface>
                        <friction>
                            <ode>
                                <mu>0.5</mu>
                                <mu2>0.5</mu2>
                            </ode>
                        </friction>
                    </surface>
                </visual>
                <collision name='collision'>
                    <geometry>
                        <cylinder>
                            <radius>0.175</radius>
                            <length>0.1</length>
                        </cylinder>
                    </geometry>
                </collision>
            </link>           
            <link name='left_back_wheel'> 
                <pose relative_to="chassis">-0.45 0.31 -0.435 -1.5707 0 0</pose> <!--angles are in radian-->
                <inertial>
                    <mass>5</mass>
                    <inertia>
                        <ixx>0.043333</ixx>
                        <ixy>0</ixy>
                        <ixz>0</ixz>
                        <iyy>0.043333</iyy>
                        <iyz>0</iyz>
                        <izz>0.08</izz>
                    </inertia>
                </inertial>
                <visual name='visual'>
                    <geometry>
                        <cylinder>
                            <radius>0.175</radius> 
                            <length>0.1</length>
                        </cylinder>
                    </geometry>
                    <material>
                        <ambient>1.0 0.0 0.0 1</ambient>
                        <diffuse>1.0 0.0 0.0 1</diffuse>
                        <specular>1.0 0.0 0.0 1</specular>
                    </material>
                    <surface>
                        <friction>
                            <ode>
                                <mu>0.5</mu>
                                <mu2>0.5</mu2>
                            </ode>
                        </friction>
                    </surface>
                </visual>
                <collision name='collision'>
                    <geometry>
                        <cylinder>
                            <radius>0.175</radius>
                            <length>0.1</length>
                        </cylinder>
                    </geometry>
                </collision>
            </link>           
            <link name='right_back_wheel'> 
                <pose relative_to="chassis">-0.45 -0.31 -0.435 -1.5707 0 0</pose> <!--angles are in radian-->
                <inertial>
                    <mass>5</mass>
                    <inertia>
                        <ixx>0.043333</ixx>
                        <ixy>0</ixy>
                        <ixz>0</ixz>
                        <iyy>0.043333</iyy>
                        <iyz>0</iyz>
                        <izz>0.08</izz>
                    </inertia>
                </inertial>
                <visual name='visual'>
                    <geometry>
                        <cylinder>
                            <radius>0.175</radius> 
                            <length>0.1</length>
                        </cylinder>
                    </geometry>
                    <material>
                        <ambient>1.0 0.0 0.0 1</ambient>
                        <diffuse>1.0 0.0 0.0 1</diffuse>
                        <specular>1.0 0.0 0.0 1</specular>
                    </material>
                    <surface>
                        <friction>
                            <ode>
                                <mu>0.5</mu>
                                <mu2>0.5</mu2>
                            </ode>
                        </friction>
                    </surface>
                </visual>
                <collision name='collision'>
                    <geometry>
                        <cylinder>
                            <radius>0.175</radius>
                            <length>0.1</length>
                        </cylinder>
                    </geometry>
                </collision>
            </link>           
            
            <link name='arm_base'> 
                <pose relative_to="chassis">0.40 0.0 0.435 0 0 0</pose> <!--angles are in radian-->
                <inertial>
                    <mass>1</mass>
                    <inertia>
                        <ixx>0.0043333</ixx>
                        <ixy>0</ixy>
                        <ixz>0</ixz>
                        <iyy>0.0043333</iyy>
                        <iyz>0</iyz>
                        <izz>0.008</izz>
                    </inertia>
                </inertial>
                <visual name='visual'>
                    <geometry>
                        <cylinder>
                            <radius>0.025</radius> 
                            <length>0.35</length>
                        </cylinder>
                    </geometry>
                    <material>
                        <ambient>0.0 1.0 0.0 1</ambient>
                        <diffuse>0.0 1.0 0.0 1</diffuse>
                        <specular>0.0 1.0 0.0 1</specular>
                    </material>
                </visual>
                <collision name='collision'>
                    <geometry>
                        <cylinder>
                            <radius>0.025</radius>
                            <length>0.35</length>
                        </cylinder>
                    </geometry>
                </collision>
            </link> 
            
            <link name='arm_hand_2'> 
                <pose relative_to="arm_base">0.20 0.0 0.175 0 1.5707 0</pose> <!--angles are in radian-->
                <inertial>
                    <mass>1</mass>
                    <inertia>
                        <ixx>0.0043333</ixx>
                        <ixy>0</ixy>
                        <ixz>0</ixz>
                        <iyy>0.0043333</iyy>
                        <iyz>0</iyz>
                        <izz>0.008</izz>
                    </inertia>
                </inertial>
                <visual name='visual'>
                    <geometry>
                        <cylinder>
                            <radius>0.025</radius> 
                            <length>0.40</length>
                        </cylinder>
                    </geometry>
                    <material>
                        <ambient>0.0 1.0 1.0 1</ambient>
                        <diffuse>0.0 1.0 1.0 1</diffuse>
                        <specular>0.0 1.0 1.0 1</specular>
                    </material>
                </visual>
                <collision name='collision'>
                    <geometry>
                        <cylinder>
                            <radius>0.025</radius>
                            <length>0.40</length>
                        </cylinder>
                    </geometry>
                </collision>
            </link> 

            <link name='arm_hand_3'> 
                <pose relative_to="arm_hand_2">0.1425 0.0 0.20 0 -1.5707 0</pose> <!--angles are in radian-->
                <inertial>
                    <mass>1</mass>
                    <inertia>
                        <ixx>0.0043333</ixx>
                        <ixy>0</ixy>
                        <ixz>0</ixz>
                        <iyy>0.0043333</iyy>
                        <iyz>0</iyz>
                        <izz>0.008</izz>
                    </inertia>
                </inertial>
                <visual name='visual'>
                    <geometry>
                        <cylinder>
                            <radius>0.025</radius> 
                            <length>0.285</length>
                        </cylinder>
                    </geometry>
                    <material>
                        <ambient>1.0 1.0 1.0 1</ambient>
                        <diffuse>1.0 1.0 1.0 1</diffuse>
                        <specular>1.0 1.0 1.0 1</specular>
                    </material>
                </visual>
                <collision name='collision'>
                    <geometry>
                        <cylinder>
                            <radius>0.025</radius>
                            <length>0.285</length>
                        </cylinder>
                    </geometry>
                </collision>
            </link>

            <link name='arm_gripper'> 
                <pose relative_to="arm_hand_3">0.0 0.0 -0.1425 0 -1.5707 0</pose> <!--angles are in radian-->
                <inertial>
                    <mass>1</mass>
                    <inertia>
                        <ixx>0.0043333</ixx>
                        <ixy>0</ixy>
                        <ixz>0</ixz>
                        <iyy>0.0043333</iyy>
                        <iyz>0</iyz>
                        <izz>0.008</izz>
                    </inertia>
                </inertial>
                <visual name='visual'>
                    <geometry>
                        <cylinder>
                            <radius>0.025</radius> 
                            <length>0.1</length>
                        </cylinder>
                    </geometry>
                    <material>
                        <ambient>1.0 1.0 0.0 1</ambient>
                        <diffuse>1.0 1.0 0.0 1</diffuse>
                        <specular>1.0 1.0 0.0 1</specular>
                    </material>
                </visual>
                <collision name='collision'>
                    <geometry>
                        <cylinder>
                            <radius>0.025</radius>
                            <length>0.1</length>
                        </cylinder>
                    </geometry>
                </collision>
            </link>
            <link name='arm_hand_3_ext'> 
                <pose relative_to="arm_hand_2">0.0 0.0 0.20 0 -1.5707 0</pose> <!--angles are in radian-->
                <inertial>
                    <mass>1</mass>
                    <inertia>
                        <ixx>0.0043333</ixx>
                        <ixy>0</ixy>
                        <ixz>0</ixz>
                        <iyy>0.0043333</iyy>
                        <iyz>0</iyz>
                        <izz>0.008</izz>
                    </inertia>
                </inertial>
                <visual name='visual'>
                    <geometry>
                        <cylinder>
                            <radius>0.03</radius> 
                            <length>0.05</length>
                        </cylinder>
                    </geometry>
                    <material>
                        <ambient>1.0 1.0 0.0 1</ambient>
                        <diffuse>1.0 1.0 0.0 1</diffuse>
                        <specular>1.0 1.0 0.0 1</specular>
                    </material>
                </visual>
                <collision name='collision'>
                    <geometry>
                        <cylinder>
                            <radius>0.03</radius>
                            <length>0.05</length>
                        </cylinder>
                    </geometry>
                </collision>
            </link>

            <link name='front_depth_camera'>
                <pose relative_to="chassis">0.40 0.5 0.4 0 0 0</pose>
                <inertial>
                    <mass>1e-10</mass>
                </inertial>
                <visual name='front_depth_camera_visual'>
                     <geometry>
                          <box>
                               <size>0.01 0.01 0.01</size>
                          </box>
                    </geometry>
                </visual>
                <sensor type="depth_camera" name="front_depth_camera">
                    <always_on>1</always_on>
                    <visualize>true</visualize>
                    <update_rate>10</update_rate>
                    <topic>/world/auv/model/auv/link/front_depth_camera/sensor/front_depth_camera/depth_image</topic>
                    <camera>
                        <horizontal_fov>2.00</horizontal_fov>
                        <image>
                            <width>320</width>
                            <height>240</height>
                            <format>R_FLOAT32</format>
                        </image>
                        <clip>
                             <near>0.1</near>
                             <far>10.0</far>
                        </clip>
                    </camera>
                </sensor>
             </link>
             <link name='front_camera'>
                <pose relative_to="chassis">0.40 0.40 0.3 0 0 0</pose>
                <inertial>
                    <mass>1e-10</mass>
                </inertial>
                <visual name='front_camera_visual'>
                     <geometry>
                         <box>
                            <size>0.01 0.01 0.01</size>
                         </box>
                    </geometry>
                </visual>
                <sensor type="camera" name="front_camera">
                    <always_on>1</always_on>
                    <visualize>true</visualize>
                    <update_rate>10</update_rate>
                    <topic>/world/auv/model/auv/link/front_camera/sensor/front_camera/image</topic>
                    <camera>
                        <horizontal_fov>2.00</horizontal_fov>
                        <image>
                            <width>320</width>
                            <height>240</height>
                        </image>
                        <clip>
                            <near>0.1</near>
                            <far>10.0</far>
                         </clip>
                    </camera>
                </sensor>
            </link>
            
            
            
            
            
            
            
            
            
            
            
            
            
            <joint name='leftf_wheel_joint' type='revolute'>
                <pose relative_to='left_front_wheel'/>
                <parent>chassis</parent>
                <child>left_front_wheel</child>
                <axis>
                    <xyz expressed_in='__model__'>0 1 0</xyz> <!--can be descired to any frame or even arbitrary frames-->
                    <limit>
                        <lower>-1.79769e+308</lower>    <!--negative infinity-->
                        <upper>1.79769e+308</upper>     <!--positive infinity-->
                    </limit>
                </axis>
            </joint>
        
            <joint name='rightf_wheel_joint' type='revolute'>
                <pose relative_to='right_front_wheel'/>
                <parent>chassis</parent>
                <child>right_front_wheel</child>
                <axis>
                    <xyz expressed_in='__model__'>0 1 0</xyz> <!--can be descired to any frame or even arbitrary frames-->
                    <limit>
                        <lower>-1.79769e+308</lower>    <!--negative infinity-->
                        <upper>1.79769e+308</upper>     <!--positive infinity-->
                    </limit>
                </axis>
            </joint>
            
            <joint name='leftb_wheel_joint' type='revolute'>
                <pose relative_to='left_back_wheel'/>
                <parent>chassis</parent>
                <child>left_back_wheel</child>
                <axis>
                    <xyz expressed_in='__model__'>0 1 0</xyz> <!--can be descired to any frame or even arbitrary frames-->
                    <limit>
                        <lower>-1.79769e+308</lower>    <!--negative infinity-->
                        <upper>1.79769e+308</upper>     <!--positive infinity-->
                    </limit>
                </axis>
            </joint>

            <joint name='rightb_wheel_joint' type='revolute'>
                <pose relative_to='right_back_wheel'/>
                <parent>chassis</parent>
                <child>right_back_wheel</child>
                <axis>
                    <xyz expressed_in='__model__'>0 1 0</xyz> <!--can be descired to any frame or even arbitrary frames-->
                    <limit>
                        <lower>-1.79769e+308</lower>    <!--negative infinity-->
                        <upper>1.79769e+308</upper>     <!--positive infinity-->
                    </limit>
                </axis>
            </joint>
            
            <joint name='arm_base_joint' type='revolute'>
                <pose relative_to='arm_base'/>
                <parent>chassis</parent>
                <child>arm_base</child>
                <axis>
                    <xyz expressed_in='__model__'>0 0 1</xyz> <!--can be descired to any frame or even arbitrary frames-->
                    <limit>
                        <lower>-1.79769e+308</lower>    <!--negative infinity-->
                        <upper>1.79769e+308</upper>     <!--positive infinity-->
                    </limit>
                </axis>
            </joint>

            <joint name='arm_joint_2' type='revolute'>
                <pose relative_to='arm_hand_2'/>
                <parent>arm_base</parent>
                <child>arm_hand_2</child>
                <axis>
                    <xyz expressed_in='__model__'>1 0 0</xyz> <!--can be descired to any frame or even arbitrary frames-->
                    <limit>
                        <lower>0</lower>    <!--fixed joint-->
                        <upper>0</upper>     <!--fixed joint-->
                    </limit>
                </axis>
            </joint>


            <!--joint name="prism_joint" type="prismatic">
                <pose relative_to='arm_hand_3_ext'/>
                <parent>arm_hand_3_ext</parent>
                <child>arm_hand_3</child>
                <axis xyz="0 0 1"/><trying all axis possibilities here>
                <limit effort="1.0" lower="-0.3" upper="0.1" velocity="0.08"/>
                <origin xyz="0 0 0" rpy="0 0 0"/>
            </joint-->
             <joint name='arm_joint_3' type='revolute'>
                <pose relative_to='arm_hand_3_ext'/>
                <parent>arm_hand_3_ext</parent>
                <child>arm_hand_3</child>
                <axis>
                    <xyz expressed_in='__model__'>0 0 1</xyz> <!--can be descired to any frame or even arbitrary frames-->
                    <limit>
                        <lower>0</lower>    <!--fixed joint-->
                        <upper>0</upper>     <!--fixed joint-->
                    </limit>
                </axis>
            </joint>

            
            <joint name='gripper_joint' type='revolute'>
                <pose relative_to='arm_hand_3'/>
                <parent>arm_hand_3</parent>
                <child>arm_gripper</child>
                <axis>
                    <xyz expressed_in='__model__'>0 0 1</xyz> <!--can be descired to any frame or even arbitrary frames-->
                    <limit>
                        <lower>-1.79769e+308</lower>    <!--negative infinity-->
                        <upper>1.79769e+308</upper>     <!--positive infinity-->   
                    </limit>
                </axis>
            </joint>
            <joint name='fixed_joint_hand2' type='fixed'>
                <parent>arm_hand_2</parent>
                <child>arm_hand_3_ext</child>
            </joint>  
            <joint name='front_depth_camera_joint' type='fixed'>
                <pose relative_to='chassis'/>
                <parent>chassis</parent>
                 <child>front_depth_camera</child>
            </joint>
            <joint name='front_camera_joint' type='fixed'>
                <pose relative_to='chassis'/>
                <parent>chassis</parent>
                <child>front_camera</child>
            </joint>

            <plugin
                filename="libignition-gazebo-diff-drive-system.so"
                name="ignition::gazebo::systems::DiffDrive">
                <num_wheel_pairs>2</num_wheel_pairs>
                <left_joint>leftf_wheel_joint</left_joint>
                <right_joint>rightf_wheel_joint</right_joint>

                <left_joint>leftb_wheel_joint</left_joint>
                <right_joint>rightb_wheel_joint</right_joint>
                <wheel_separation>0.62</wheel_separation>
                <wheel_radius>0.175</wheel_radius>
                <odom_publish_frequency>50</odom_publish_frequency>
                <topic>cmd_vel</topic>
            </plugin>

        
        </model> 
        <model name='wall'>
            <pose>5 0 0 0 0 0</pose>
            <link name='box'>
                <pose/>
                <inertial>
                    <mass>1.14</mass>
                    <inertia>
                        <ixx>9.532</ixx>
                        <ixy>0</ixy>
                        <ixz>0</ixz> 
                        <iyy>10.0</iyy>
                        <iyz>0</iyz>
                        <izz>8</izz>
                    </inertia>
                </inertial>      
                <visual name='visual'>
                    <geometry>
                        <box>
                            <size>0.5 10.0 2.0</size>
                        </box>
                    </geometry>
                    <material>
                        <ambient>0.0 0.0 1.0 1</ambient>
                        <diffuse>0.0 0.0 1.0 1</diffuse>
                        <specular>0.0 0.0 1.0 1</specular>
                    </material>
                </visual>
                <collision name='collision'>
                    <geometry>
                        <box> 
                             <size>0.5 10.0 2.0</size>
                        </box>
                    </geometry>
                </collision>
            </link>
        </model>                              
        <plugin filename='libignition-gazebo-triggered-publisher-system.so'
                name="ignition::gazebo::systems::TriggeredPublisher">
            <input type ="ignition.msgs.Int32" topic="/keyboard/keypress">
                <match field="data">16777235</match>
            </input>
            <output type="ignition.msgs.Twist" topic="/cmd_vel">
                linear: {x: 0.5}, angular: {z: 0.0}<!--forward-->
            </output>
        </plugin>
        <plugin filename='libignition-gazebo-triggered-publisher-system.so'
                name="ignition::gazebo::systems::TriggeredPublisher">
            <input type ="ignition.msgs.Int32" topic="/keyboard/keypress">
                <match field="data">16777237</match><!--backward-->
            </input>
            <output type="ignition.msgs.Twist" topic="/cmd_vel">
                linear: {x: -0.5}, angular: {z: 0.0}
            </output>
        </plugin>
        <plugin filename='libignition-gazebo-triggered-publisher-system.so'
                name="ignition::gazebo::systems::TriggeredPublisher">
            <input type ="ignition.msgs.Int32" topic="/keyboard/keypress">
                <match field="data">16777234</match>
            </input>
            <output type="ignition.msgs.Twist" topic="/cmd_vel">
                linear: {x: 0.0}, angular: {z: 0.5}<!--left-->
            </output>
        </plugin>
        <plugin filename='libignition-gazebo-triggered-publisher-system.so'
                name="ignition::gazebo::systems::TriggeredPublisher">
            <input type ="ignition.msgs.Int32" topic="/keyboard/keypress">
                <match field="data">16777236</match><!--right-->
            </input>
            <output type="ignition.msgs.Twist" topic="/cmd_vel">
                linear: {x: 0.0}, angular: {z: -0.5}
            </output>
        </plugin>        
        
    </world>
</sdf>    